#VRML_SIM R2023b utf8

EXTERNPROTO "https://raw.githubusercontent.com/cyberbotics/webots/R2023b/projects/objects/backgrounds/protos/TexturedBackground.proto"
EXTERNPROTO "https://raw.githubusercontent.com/cyberbotics/webots/R2023b/projects/objects/backgrounds/protos/TexturedBackgroundLight.proto"
EXTERNPROTO "https://raw.githubusercontent.com/cyberbotics/webots/R2023b/projects/objects/floors/protos/Floor.proto"
EXTERNPROTO "https://raw.githubusercontent.com/cyberbotics/webots/R2023b/projects/appearances/protos/Parquetry.proto"
EXTERNPROTO "https://raw.githubusercontent.com/cyberbotics/webots/R2023b/projects/appearances/protos/Asphalt.proto"

WorldInfo {
}
Viewpoint {
  orientation -0.3271224677960418 0.03928976320583086 0.9441648190704085 2.9157640897168537
  position 4.110374846278215 -1.2936022904098199 4.43265866468333
}
TexturedBackground {
}
TexturedBackgroundLight {
}
Floor {
  size 20 20
  appearance Parquetry {
  }
}
Robot {
  translation 0.20000011548514046 0.010112846125018926 0.1451039407046274
  rotation 0.9999999999999786 1.3863939691939194e-07 1.5460470441463585e-07 1.5700522518307254
  children [
    SliderJoint {
      jointParameters JointParameters {
        position -5.940954933927516e-08
        minStop -0.5
        maxStop 0.5
      }
      device [
        LinearMotor {
          name "ilk_motor"
          minPosition -0.5
          maxPosition 0.5
        }
      ]
      endPoint Solid {
        translation 0 0.2 -0.04000005940954934
        children [
          Shape {
            appearance Asphalt {
            }
            geometry Box {
              size 1 0.1 0.1
            }
          }
          SliderJoint {
            jointParameters JointParameters {
              position 2.138448123114924e-12
              axis 1 0 0
              minStop -0.5
              maxStop 0.5
            }
            device [
              LinearMotor {
                name "ikinci_motor"
                minPosition -0.5
                maxPosition 0.5
              }
            ]
            endPoint Solid {
              translation 2.138448123114924e-12 0.06 0
              children [
                DEF kol_tabla Shape {
                  appearance Asphalt {
                  }
                  geometry Box {
                    size 0.3 0.02 0.3
                  }
                }
              ]
              boundingObject USE kol_tabla
              physics Physics {
              }
            }
          }
        ]
        boundingObject DEF kol_yatay Shape {
          appearance Asphalt {
          }
          geometry Box {
            size 1 0.1 0.1
          }
        }
        physics Physics {
        }
      }
    }
    DEF sasi Shape {
      appearance Asphalt {
      }
      geometry Box {
        size 0.3 0.3 1
      }
    }
  ]
  boundingObject USE sasi
  physics Physics {
    density 7.85
  }
  controller "kol_kontrolcu"
}
