#VRML_SIM R2023b utf8

EXTERNPROTO "https://raw.githubusercontent.com/cyberbotics/webots/R2023b/projects/objects/backgrounds/protos/TexturedBackground.proto"
EXTERNPROTO "https://raw.githubusercontent.com/cyberbotics/webots/R2023b/projects/objects/backgrounds/protos/TexturedBackgroundLight.proto"
EXTERNPROTO "https://raw.githubusercontent.com/cyberbotics/webots/R2023b/projects/objects/floors/protos/Floor.proto"
EXTERNPROTO "https://raw.githubusercontent.com/cyberbotics/webots/R2023b/projects/appearances/protos/GalvanizedMetal.proto"
EXTERNPROTO "https://raw.githubusercontent.com/cyberbotics/webots/R2023b/projects/appearances/protos/ThreadMetalPlate.proto"

WorldInfo {
}
Viewpoint {
  fieldOfView 1
  orientation 0.08676176195973803 0.09612329370570508 -0.9915809140301202 1.47689095322095
  position -0.6652035347373035 6.447334027520144 2.2052292434241147
}
TexturedBackground {
}
TexturedBackgroundLight {
}
Floor {
  tileSize 1 1
}
DEF KOL Robot {
  translation 5.5687912186625757e-11 -2.4899925982564772 1.1347209446759712
  rotation -0.9999999999716981 7.523536553079165e-06 1.4729821694385004e-13 6.492757889621617e-06
  children [
    DEF KOL_DIKEYDE SliderJoint {
      jointParameters JointParameters {
        maxStop 2
      }
      device [
        LinearMotor {
          name "DIKEY_MOTOR"
          maxPosition 2
        }
      ]
      endPoint DEF KOL_DIKEYDE Solid {
        translation 3.74154e-06 0.382623 0.269
        rotation 0.9999994860737339 0.0010138304927966265 -9.58974466132539e-09 -0.0026253071795858673
        children [
          DEF KOL_YATAYDA SliderJoint {
            jointParameters JointParameters {
              position -5.521773333483277e-10
              axis 1 0 0
              minStop -1
              maxStop 1
            }
            device [
              DEF YATAY_MOTOR LinearMotor {
                name "YATAY_MOTOR"
                minPosition -1
                maxPosition 1
              }
            ]
            endPoint DEF KOL_YATAYDA Solid {
              translation -6.746046238759102e-10 0.1800000023242624 8.971998710638474e-07
              rotation 0.9690416945605195 0.24689625285207967 -0.0006591895622120961 1.6854736050280288e-06
              children [
                DEF dikey_mesafe DistanceSensor {
                  translation -6.16209e-14 0.00999937 -0.41
                  rotation -0.7071067811862364 9.381857096790023e-07 0.7071067811862364 3.14159
                  children [
                    DEF dikey_mesafe Solid {
                      translation -6.74634e-14 0 -2.51033e-13
                      rotation 0 1 0 1.5708
                      children [
                        DEF dikey_mesafe Shape {
                          appearance PBRAppearance {
                            baseColor 1 1 0
                            roughness 1
                            metalness 0
                          }
                          geometry Cone {
                            bottomRadius 0.1
                            height 0.1
                          }
                        }
                      ]
                    }
                  ]
                  name "dikey_mesafe"
                  lookupTable [
                    0 0 0
                    5 1000 0
                  ]
                  type "laser"
                }
                DEF TUTAMAC_SOL SliderJoint {
                  jointParameters JointParameters {
                    axis 0 1 0
                    minStop -1.1
                  }
                  device [
                    LinearMotor {
                      name "TUTAMAC_SOL"
                      minPosition -1
                    }
                  ]
                  endPoint DEF TUTAMAC_SOL Solid {
                    translation -0.33 0.51 -0.35
                    children [
                      DEF TUTAMAC_SOL Shape {
                        appearance ThreadMetalPlate {
                        }
                        geometry Box {
                          size 0.1 1.1 0.05
                        }
                      }
                    ]
                    name "solid(1)"
                    boundingObject USE TUTAMAC_SOL
                    physics Physics {
                      density 2
                    }
                  }
                }
                DEF TUTAMAC_SAG SliderJoint {
                  jointParameters JointParameters {
                    axis 0 1 0
                    minStop -1.1
                  }
                  device [
                    LinearMotor {
                      name "TUTAMAC_SAG"
                      acceleration 10
                      minPosition -1
                    }
                  ]
                  endPoint DEF TUTAMAC_SAG Solid {
                    translation 0.33 0.54 -0.35
                    children [
                      DEF TUTAMAC_SAG Shape {
                        appearance ThreadMetalPlate {
                        }
                        geometry Box {
                          size 0.1 1.1 0.05
                        }
                      }
                    ]
                    boundingObject USE TUTAMAC_SAG
                    physics Physics {
                      density 2
                    }
                  }
                }
                DEF KOL_YATAYDA Shape {
                  appearance GalvanizedMetal {
                  }
                  geometry Box {
                    size 0.75 0.1 0.75
                  }
                }
              ]
              boundingObject USE KOL_YATAYDA
              physics Physics {
                density 1
              }
            }
          }
          DEF KOL_DIKEYDE Shape {
            appearance GalvanizedMetal {
            }
            geometry Box {
              size 2 0.25 0.25
            }
          }
        ]
        boundingObject USE KOL_DIKEYDE
        physics Physics {
          density 1
        }
      }
    }
    DEF SASI Group {
      children [
        DEF ARKA_AYAK Pose {
          translation 0 0 -0.89
          children [
            DEF ARKA_AYAK Shape {
              appearance ThreadMetalPlate {
              }
              geometry Box {
                size 5 5 0.5
              }
            }
          ]
        }
        DEF GOVDE Pose {
          translation 0 0 0.65
          children [
            DEF GOVDE Shape {
              appearance GalvanizedMetal {
              }
              geometry Box {
                size 0.5 0.5 3
              }
            }
          ]
        }
      ]
    }
  ]
  name "KOL"
  boundingObject USE SASI
  physics Physics {
    density 1
  }
  controller "KOL_KONTROLCU_V2"
}
